Traceback (most recent call last):
  File "/home/dell/.local/lib/python3.6/site-packages/jupyter_cache/executors/utils.py", line 56, in single_nb_execution
    record_timing=False,
  File "/home/dell/.local/lib/python3.6/site-packages/nbclient/client.py", line 1087, in execute
    return NotebookClient(nb=nb, resources=resources, km=km, **kwargs).execute()
  File "/home/dell/.local/lib/python3.6/site-packages/nbclient/util.py", line 74, in wrapped
    return just_run(coro(*args, **kwargs))
  File "/home/dell/.local/lib/python3.6/site-packages/nbclient/util.py", line 53, in just_run
    return loop.run_until_complete(coro)
  File "/home/dell/miniconda3/envs/deepai-book/lib/python3.6/asyncio/base_events.py", line 488, in run_until_complete
    return future.result()
  File "/home/dell/.local/lib/python3.6/site-packages/nbclient/client.py", line 541, in async_execute
    cell, index, execution_count=self.code_cells_executed + 1
  File "/home/dell/.local/lib/python3.6/site-packages/nbclient/client.py", line 832, in async_execute_cell
    self._check_raise_for_error(cell, exec_reply)
  File "/home/dell/.local/lib/python3.6/site-packages/nbclient/client.py", line 740, in _check_raise_for_error
    raise CellExecutionError.from_cell_and_msg(cell, exec_reply['content'])
nbclient.exceptions.CellExecutionError: An error occurred while executing the following cell:
------------------
for col in ['REASON', 'JOB']:
  df_summary, IV, thres = _WOE(data, colname=col)category
  WOE_dict[col] = {'table':df_summary, 'IV':IV}
------------------

[0;36m  File [0;32m"<ipython-input-13-e14c5a8db0fb>"[0;36m, line [0;32m2[0m
[0;31m    df_summary, IV, thres = _WOE(data, colname=col)category[0m
[0m                                                          ^[0m
[0;31mSyntaxError[0m[0;31m:[0m invalid syntax

SyntaxError: invalid syntax (<ipython-input-13-e14c5a8db0fb>, line 2)

